#VRML_SIM R2023b utf8

EXTERNPROTO "https://raw.githubusercontent.com/cyberbotics/webots/R2022b/projects/objects/backgrounds/protos/TexturedBackground.proto"
EXTERNPROTO "https://raw.githubusercontent.com/cyberbotics/webots/R2022b/projects/objects/backgrounds/protos/TexturedBackgroundLight.proto"
EXTERNPROTO "https://raw.githubusercontent.com/cyberbotics/webots/R2022b/projects/objects/floors/protos/CircleArena.proto"
EXTERNPROTO "https://raw.githubusercontent.com/cyberbotics/webots/R2023b/projects/objects/factory/containers/protos/WoodenBox.proto"
EXTERNPROTO "https://raw.githubusercontent.com/cyberbotics/webots/R2022b/projects/appearances/protos/BrushedAluminium.proto"

WorldInfo {
}
Viewpoint {
  orientation 0.01560892564701466 0.9193892585205324 -0.39303912369789806 0.7219726451279164
  position -4.46767047889079 1.4496795896701606 3.5425007850920895
  follow "my_robot"
}
TexturedBackground {
}
TexturedBackgroundLight {
}
CircleArena {
  radius 1.5
  wallHeight 0.3
  wallAppearance BrushedAluminium {
    colorOverride 0.6 0.756863 0.945098
    textureTransform TextureTransform {
    }
    IBLStrength 21
  }
}
WoodenBox {
  translation 0.823045 -0.225488 0.09
  name "wooden box(5)"
  size 0.3 0.2 0.2
  mass 30
}
WoodenBox {
  translation 0.429385 0.572554 0.09
  rotation 0 0 1 -0.785395307179586
  name "wooden box(4)"
  size 0.3 0.2 0.2
  mass 30
}
WoodenBox {
  translation -0.204004 -0.520756 0.09
  name "wooden box(3)"
  size 0.3 0.2 0.2
  mass 30
}
Robot {
  children [
    InertialUnit {
      name "inertial_unit"
      translation 0 0 0.1
    }
    Accelerometer {
      name "accelerometer"
      translation 0 0 0.1
    }
    Gyro {
      name "gyro"
      translation 0 0 0.1
    }
    Lidar {
      name "lidar"
      translation 0 0 0.1
      horizontalResolution 1024
      fieldOfView 6.28
      verticalFieldOfView 0.3
      numberOfLayers 1
      minRange 0.1
      maxRange 4
      defaultFrequency 10
      minFrequency 1
      maxFrequency 25
    }
    HingeJoint {
      jointParameters HingeJointParameters {
        axis 0 1 0
        anchor 0 0 0.025
      }
      device [
        RotationalMotor {
          name "left wheel motor"
        }
      ]
      endPoint Solid {
        translation 0 0.045 0.025
        children [
          DEF WHEEL Pose {
            rotation 1 0 0 1.5707996938995747
            children [
              Shape {
                appearance PBRAppearance {
                  baseColor 1 0 0
                  roughness 1
                  metalness 0
                }
                geometry Cylinder {
                  height 0.01
                  radius 0.025
                }
              }
            ]
          }
        ]
        name "left wheel"
        boundingObject USE WHEEL
        physics Physics {
        }
      }
    }
    HingeJoint {
      jointParameters HingeJointParameters {
        axis 0 1 0
        anchor 0 0 0.025
      }
      device [
        RotationalMotor {
          name "right wheel motor"
        }
      ]
      endPoint Solid {
        translation 0 -0.045 0.025
        children [
          USE WHEEL
        ]
        name "right wheel"
        boundingObject USE WHEEL
        physics Physics {
        }
      }
    }
    Pose {
      translation 0 0 0.0415
      children [
        Shape {
          appearance PBRAppearance {
            baseColor 0 0 1
            roughness 1
            metalness 0
          }
          geometry DEF BODY Cylinder {
            height 0.08
            radius 0.045
          }
        }
      ]
    }
#    DistanceSensor {
#      translation 0.042 0.02 0.063
#      rotation 0 0 1 0.5236003061004253
#      children [
#        DEF SENSOR Pose {
#          rotation 0 1 0 1.5708
#          children [
#            Shape {
#              appearance PBRAppearance {
#                baseColor 1 1 0
#                roughness 1
#                metalness 0
#              }
#              geometry Cylinder {
#                height 0.004
#                radius 0.008
#              }
#            }
#          ]
#        }
#      ]
#      name "ds0"
#      lookupTable [
#        0 1020 0
#        0.05 1020 0
#        0.15 0 0
#      ]
#      numberOfRays 2
#      aperture 1
#    }
#    DistanceSensor {
#      translation 0.042 -0.02 0.063
#      rotation 0 0 1 -0.5235996938995747
#      children [
#        USE SENSOR
#      ]
#      name "ds1"
#      lookupTable [
#        0 1020 0
#        0.05 1020 0
#        0.15 0 0
#      ]
#      numberOfRays 2
#      aperture 1
#    }
  ]
  name "my_robot"
  boundingObject Pose {
    translation 0 0 0.0415
    children [
      USE BODY
    ]
  }
  physics Physics {
  }
  controller "<extern>"
}
WoodenBox {
  translation -0.890968 0.0729998 0.09
  rotation 0 0 1 -0.785395307179586
  size 0.3 0.2 0.2
  mass 30
}
WoodenBox {
  translation 0.430022 -0.832108 0.09
  rotation 0 0 1 0.523599
  name "wooden box(1)"
  size 0.3 0.2 0.2
  mass 30
}
WoodenBox {
  translation -0.342252 0.956004 0.09
  rotation 0 0 1 0.261799
  name "wooden box(2)"
  size 0.3 0.2 0.2
  mass 30
}
