<?xml version="1.0" ?>
<robot name="My robot">
    <webots>
        <!-- <device reference="ds0" type="DistanceSensor">
            <ros>
                <topicName>/left_sensor</topicName>
                <alwaysOn>true</alwaysOn>
                <enabled>true</enabled>
                <frameName>ds</frameName>
            </ros>
        </device>

        <device reference="ds1" type="DistanceSensor">
            <ros>
                <topicName>/right_sensor</topicName>
                <alwaysOn>true</alwaysOn>
                <enabled>true</enabled>
                <frameName>ds</frameName>
            </ros>
        </device> -->

        <device reference="lidar" type="Lidar">
            <ros>
                <enabled>true</enabled>
                <updateRate>10</updateRate>
                <topicName>/scan</topicName>
                <alwaysOn>true</alwaysOn>
                <!-- <frameName>lidar</frameName> -->
                <frameName>lidar</frameName>
            </ros>
        </device>
        
        <plugin type="webots_ros2_driver::Ros2IMU">
            <enabled>true</enabled>
            <updateRate>20</updateRate>
            <topicName>/imu</topicName>
            <alwaysOn>true</alwaysOn>
            <!-- <frameName>imu_link</frameName> -->
            <frameName>inertial_unit</frameName>
            <inertialUnitName>inertial_unit</inertialUnitName>
            <gyroName>gyro</gyroName>
            <accelerometerName>accelerometer</accelerometerName>
        </plugin>

        <plugin type="my_robot::MyRobotDriver" />
    </webots>

    <link name="base_link">
        <visual>
            <origin xyz="0 0 0.0415" rpy="0 0 0"/>
            <geometry>
            <cylinder radius="0.045" length="0.08"/>
            </geometry>
        </visual>
        <collision>
            <origin xyz="0 0 0.0415" rpy="0 0 0"/>
            <geometry>
                <cylinder radius="0.045" length="0.08"/>
            </geometry>
        </collision>
    </link>

    <link name="lidar">
    </link>
    <joint name="base_link_lidar_joint" type="fixed">
        <parent link="base_link"/>
        <child link="lidar"/>
        <origin xyz="0 0 0.1" rpy="0 0 0"/>
    </joint>

     <link name="gyro">
    </link>
    <joint name="base_link_gyro_joint" type="fixed">
        <parent link="base_link"/>
        <child link="gyro"/>
        <origin xyz="0 0 0.1" rpy="0 0 0"/>
    </joint>

    <link name="accelerometer">
    </link>
    <joint name="base_link_accelerometer_joint" type="fixed">
        <parent link="base_link"/>
        <child link="accelerometer"/>
        <origin xyz="0 0 0.1" rpy="0 0 0"/>
    </joint>

    <link name="inertial_unit">
    </link>
    <joint name="base_link_inertial_unit_joint" type="fixed">
        <parent link="base_link"/>
        <child link="inertial_unit"/>
        <origin xyz="0 0 0.1" rpy="0 0 0"/>
    </joint>

  <joint name="right wheel motor" type="continuous">
    <parent link="base_link"/>
    <child link="right wheel"/>
    <axis xyz="0 1 0"/>
    <limit effort="10" velocity="10"/>
    <origin xyz="0 0 0.025" rpy="0 0.000001 0"/>
  </joint>

  <link name="right wheel">
    <visual>
      <origin xyz="0 -0.045 0" rpy="1.5708 0 0"/>
      <geometry>
        <cylinder radius="0.025" length="0.01"/>
      </geometry>
    </visual>
    <collision>
      <origin xyz="0 -0.045 0" rpy="1.5708 0 0"/>
      <geometry>
        <cylinder radius="0.025" length="0.01"/>
      </geometry>
    </collision>
  </link>

  <joint name="left wheel motor" type="continuous">
    <parent link="base_link"/>
    <child link="left wheel"/>
    <axis xyz="0 1 0"/>
    <limit effort="10" velocity="10"/>
    <origin xyz="0 -0.045 0.025" rpy="0 0 0"/>
  </joint>

  <link name="left wheel">
    <visual>
      <origin xyz="0 0.045 0" rpy="1.5708 0 0"/>
      <geometry>
        <cylinder radius="0.025" length="0.01"/>
      </geometry>
    </visual>
    <collision>
      <origin xyz="0 0.045 0" rpy="1.5708 0 0"/>
      <geometry>
        <cylinder radius="0.025" length="0.01"/>
      </geometry>
    </collision>
  </link>
  

</robot>
